Workbook

Sheet Dashboard
B2: Financial Model Dashboard
B4: Historical Performance & 5-Year Forecast
B5: Forecast - 2021
B6: Revenue | C6: EBITDA | D6: Net Income | E6: FCF
B7: ='P&L'!M5 -> 3524.1932 | C7: ='P&L'!M9 -> 704.83864 | D7: ='P&L'!M15 -> 402.0626 | E7: ='Financial Analysis'!J29 -> 380.13242
F10: Forecast
C11: =YEAR(BS!C6) -> 2014 | D11: =YEAR(BS!D6) -> 2015 | E11: =YEAR(BS!E6) -> 2016 | F11: =YEAR(BS!F6) -> 2017 | G11: =YEAR(BS!G6) -> 2018 | H11: =YEAR(BS!H6) -> 2019 | I11: =YEAR(BS!I6) -> 2020 | J11: =YEAR(BS!J6) -> 2021
B12: Revenue | C12: ='P&L'!C5 -> 2922 | D12: ='P&L'!D5 -> 2984 | E12: ='P&L'!E5 -> 3040 | F12: ='P&L'!I5 -> 3131.2 | G12: ='P&L'!J5 -> 3225.136 | H12: ='P&L'!K5 -> 3321.8901 | I12: ='P&L'!L5 -> 3421.5468 | J12: ='P&L'!M5 -> 3524.1932
B13: EBITDA | C13: ='P&L'!C9 -> 308.82 | D13: ='P&L'!D9 -> 355.66 | E13: ='P&L'!E9 -> 604.76 | F13: ='P&L'!I9 -> 626.24 | G13: ='P&L'!J9 -> 645.0272 | H13: ='P&L'!K9 -> 664.37802 | I13: ='P&L'!L9 -> 684.30936 | J13: ='P&L'!M9 -> 704.83864
B14: Free Cash Flow | D14: ='Financial Analysis'!D29 -> 9.88 | E14: ='Financial Analysis'!E29 -> 218.18 | F14: ='Financial Analysis'!F29 -> 366.55198 | G14: ='Financial Analysis'!G29 -> 336.35702 | H14: ='Financial Analysis'!H29 -> 350.35791 | I14: ='Financial Analysis'!I29 -> 364.93928 | J14: ='Financial Analysis'!J29 -> 380.13242

Sheet Financial Analysis
B2: Financial Analysis
C4: 2014 | D4: 2015 | E4: 2016 | F4: 2017 | G4: 2018 | H4: 2019 | I4: 2020 | J4: 2021
B6: Growth Analysis
B7: Revenue | D7: =('P&L'!D5/'P&L'!C5)-1 -> 0.021218344 | E7: =('P&L'!E5/'P&L'!D5)-1 -> 0.018766756 | F7: ='P&L'!I5/'P&L'!E5-1 -> 0.03 | G7: ='P&L'!J5/'P&L'!I5-1 -> 0.03 | H7: ='P&L'!K5/'P&L'!J5-1 -> 0.03 | I7: ='P&L'!L5/'P&L'!K5-1 -> 0.03 | J7: ='P&L'!M5/'P&L'!L5-1 -> 0.03
B8: EBITDA | D8: ='P&L'!D9/'P&L'!C9-1 -> 0.15167411 | E8: ='P&L'!E9/'P&L'!D9-1 -> 0.70038801 | F8: ='P&L'!I9/'P&L'!E9-1 -> 0.035518222 | G8: ='P&L'!J9/'P&L'!I9-1 -> 0.03 | H8: ='P&L'!K9/'P&L'!J9-1 -> 0.03 | I8: ='P&L'!L9/'P&L'!K9-1 -> 0.03 | J8: ='P&L'!M9/'P&L'!L9-1 -> 0.03
B9: Net Income | D9: ='P&L'!D15/'P&L'!C15-1 -> 1.565035 | E9: ='P&L'!E15/'P&L'!D15-1 -> 7.2655398 | F9: ='P&L'!I15/'P&L'!E15-1 -> 0.13087688 | G9: ='P&L'!J15/'P&L'!I15-1 -> 0.040618485 | H9: ='P&L'!K15/'P&L'!J15-1 -> 0.040610683 | I9: ='P&L'!L15/'P&L'!K15-1 -> 0.04062158 | J9: ='P&L'!M15/'P&L'!L15-1 -> 0.040651144
B11: Profitability Analysis
B12: Gross Margin | C12: ='P&L'!C7/'P&L'!C5-1 -> -0.47946612 | D12: ='P&L'!D7/'P&L'!D5-1 -> -0.46347185 | E12: ='P&L'!E7/'P&L'!E5-1 -> -0.44967105 | F12: ='P&L'!I7/'P&L'!I5-1 -> -0.45 | G12: ='P&L'!J7/'P&L'!J5-1 -> -0.45 | H12: ='P&L'!K7/'P&L'!K5-1 -> -0.45 | I12: ='P&L'!L7/'P&L'!L5-1 -> -0.45 | J12: ='P&L'!M7/'P&L'!M5-1 -> -0.45
B13: EBITDA Margin | C13: ='P&L'!C9/'P&L'!C5-1 -> -0.89431211 | D13: ='P&L'!D9/'P&L'!D5-1 -> -0.88081099 | E13: ='P&L'!E9/'P&L'!E5-1 -> -0.80106579 | F13: ='P&L'!I9/'P&L'!I5-1 -> -0.8 | G13: ='P&L'!J9/'P&L'!J5-1 -> -0.8 | H13: ='P&L'!K9/'P&L'!K5-1 -> -0.8 | I13: ='P&L'!L9/'P&L'!L5-1 -> -0.8 | J13: ='P&L'!M9/'P&L'!M5-1 -> -0.8
B14: EBIT Margin | C14: ='P&L'!C11/'P&L'!C5-1 -> -0.90492129 | D14: ='P&L'!D11/'P&L'!D5-1 -> -0.8955563 | E14: ='P&L'!E11/'P&L'!E5-1 -> -0.81455263 | F14: ='P&L'!I11/'P&L'!I5-1 -> -0.81415247 | G14: ='P&L'!J11/'P&L'!J5-1 -> -0.81403354 | H14: ='P&L'!K11/'P&L'!K5-1 -> -0.8139156 | I14: ='P&L'!L11/'P&L'!L5-1 -> -0.81379865 | J14: ='P&L'!M11/'P&L'!M5-1 -> -0.81368269
B15: Net Profit Margin | C15: ='P&L'!C15/'P&L'!C5-1 -> -0.99510609 | D15: ='P&L'!D15/'P&L'!D5-1 -> -0.98770777 | E15: ='P&L'!E15/'P&L'!E5-1 -> -0.90026974 | F15: ='P&L'!I15/'P&L'!I5-1 -> -0.89050228 | G15: ='P&L'!J15/'P&L'!J5-1 -> -0.88937345 | H15: ='P&L'!K15/'P&L'!K5-1 -> -0.88823381 | I15: ='P&L'!L15/'P&L'!L5-1 -> -0.88708126 | J15: ='P&L'!M15/'P&L'!M5-1 -> -0.88591357
B17: Liquidity Analysis
B18: Current Ratio | C18: =(BS!C7+BS!C8+BS!C10+BS!C11)/(BS!C14+BS!C15+BS!C17) -> 2.0134409 | D18: =(BS!D7+BS!D8+BS!D10+BS!D11)/(BS!D14+BS!D15+BS!D17) -> 2.2391767 | E18: =(BS!E7+BS!E8+BS!E10+BS!E11)/(BS!E14+BS!E15+BS!E17) -> 4.156044 | F18: =(BS!F7+BS!F10+BS!F11)/(BS!F14+BS!F15+BS!F16) -> 0.94826141 | G18: =(BS!G7+BS!G10+BS!G11)/(BS!G14+BS!G15+BS!G16) -> 1.2631583 | H18: =(BS!H7+BS!H10+BS!H11)/(BS!H14+BS!H15+BS!H16) -> 1.6414173 | I18: =(BS!I7+BS!I10+BS!I11)/(BS!I14+BS!I15+BS!I16) -> 2.1089329 | J18: =(BS!J7+BS!J10+BS!J11)/(BS!J14+BS!J15+BS!J16) -> 2.7081
B19: Debt/Equity | C19: =(BS!C15+BS!C16)/BS!C18 -> 3.8704478 | D19: =(BS!D15+BS!D16)/BS!D18 -> 3.2491103 | E19: =(BS!E15+BS!E16)/BS!E18 -> 1.3057902 | F19: =(BS!F15+BS!F16)/BS!F18 -> 0.85942906 | G19: =(BS!G15+BS!G16)/BS!G18 -> 0.60819989 | H19: =(BS!H15+BS!H16)/BS!H18 -> 0.4461244 | I19: =(BS!I15+BS!I16)/BS!I18 -> 0.33213504 | J19: =(BS!J15+BS!J16)/BS!J18 -> 0.24697422
B20: Interest Coverage | C20: ='P&L'!C11/ABS('P&L'!C12) -> 4.9610714 | D20: ='P&L'!D11/ABS('P&L'!D12) -> 4.7947692 | E20: ='P&L'!E11/ABS('P&L'!E12) -> 10.841538 | F20: ='P&L'!E11/ABS('P&L'!E12) -> 10.841538 | G20: ='P&L'!I11/ABS('P&L'!I12) -> 10.687342 | H20: ='P&L'!J11/ABS('P&L'!J12) -> 11.791098 | I20: ='P&L'!K11/ABS('P&L'!K12) -> 13.163472 | J20: ='P&L'!L11/ABS('P&L'!L12) -> 14.919735
B22: Efficiency Analysis
B23: DSO | C23: =BS!C21 -> 17.728953 | D23: =BS!D21 -> 18.675603 | E23: =BS!E21 -> 20.048684 | F23: =BS!F21 -> 18.817747 | G23: =BS!G21 -> 18.817747 | H23: =BS!H21 -> 18.817747 | I23: =BS!I21 -> 18.817747 | J23: =BS!J21 -> 18.817747
B24: DIO | C24: =BS!C23 -> 21.841542 | D24: =BS!D23 -> 23.947939 | E24: =BS!E23 -> 28.968544 | F24: =BS!F23 -> 24.919342 | G24: =BS!G23 -> 24.919342 | H24: =BS!H23 -> 24.919342 | I24: =BS!I23 -> 24.919342 | J24: =BS!J23 -> 24.919342
B25: DPO | C25: =BS!C22 -> 17.473233 | D25: =BS!D22 -> 17.934924 | E25: =BS!E22 -> 18.144843 | F25: =BS!F22 -> 17.851 | G25: =BS!G22 -> 17.851 | H25: =BS!H22 -> 17.851 | I25: =BS!I22 -> 17.851 | J25: =BS!J22 -> 17.851
B26: Asset Turnover | C26: ='P&L'!C5/BS!C12 -> 3.1348568 | D26: ='P&L'!D5/((BS!D12+BS!C12)/2) -> 3.1742992 | E26: ='P&L'!E5/((BS!E12+BS!D12)/2) -> 2.7956594 | F26: ='P&L'!I5/((BS!F12+BS!F12)/2) -> 2.235746 | G26: ='P&L'!J5/((BS!G12+BS!G12)/2) -> 2.0481581 | H26: ='P&L'!K5/((BS!H12+BS!H12)/2) -> 1.8942416 | I26: ='P&L'!L5/((BS!I12+BS!I12)/2) -> 1.7658662 | J26: ='P&L'!M5/((BS!J12+BS!J12)/2) -> 1.6573367
B27: Cash Conversion cycle | C27: =C23+C24-C25 -> 22.097261 | D27: =D23+D24-D25 -> 24.688618 | E27: =E23+E24-E25 -> 30.872386 | F27: =F23+F24-F25 -> 25.886088 | G27: =G23+G24-G25 -> 25.886088 | H27: =H23+H24-H25 -> 25.886088 | I27: =I23+I24-I25 -> 25.886088 | J27: =J23+J24-J25 -> 25.886088
B29: FCF | D29: ='Cash Flow Statement'!C17-'PP&E'!D8 -> 9.88 | E29: ='Cash Flow Statement'!D17-'PP&E'!E8 -> 218.18 | F29: ='Cash Flow Statement'!E17-'PP&E'!F8 -> 366.55198 | G29: ='Cash Flow Statement'!F17-'PP&E'!G8 -> 336.35702 | H29: ='Cash Flow Statement'!G17-'PP&E'!H8 -> 350.35791 | I29: ='Cash Flow Statement'!H17-'PP&E'!I8 -> 364.93928 | J29: ='Cash Flow Statement'!I17-'PP&E'!J8 -> 380.13242

Sheet P&L
B1: P&L
B3: Scenario | C3: Best case | I3: Forecast
B4: $ in million | C4: 2014 | D4: 2015 | E4: 2016 | G4: Var % 14-15 | H4: Var % 15-16 | I4: 2017 | J4: 2018 | K4: 2019 | L4: 2020 | M4: 2021
B5: Revenue | C5: =+SUMIFS(Workings!$E:$E,Workings!$F:$F,'P&L'!$B5,Workings!$C:$C,'P&L'!C$4) -> 2922 | D5: =+SUMIFS(Workings!$E:$E,Workings!$F:$F,'P&L'!$B5,Workings!$C:$C,'P&L'!D$4) -> 2984 | E5: =+SUMIFS(Workings!$E:$E,Workings!$F:$F,'P&L'!$B5,Workings!$C:$C,'P&L'!E$4) -> 3040 | G5: =D5/C5-1 -> 0.021218344 | H5: =E5/D5-1 -> 0.018766756 | I5: =E5*(1+I19) -> 3131.2 | J5: =I5*(1+J19) -> 3225.136 | K5: =J5*(1+K19) -> 3321.8901 | L5: =K5*(1+L19) -> 3421.5468 | M5: =L5*(1+M19) -> 3524.1932
B6: Cost of goods sold | C6: =-1*SUMIFS(Workings!$E:$E,Workings!$F:$F,'P&L'!$B6,Workings!$C:$C,'P&L'!C$4) -> -1401 | D6: =-1*SUMIFS(Workings!$E:$E,Workings!$F:$F,'P&L'!$B6,Workings!$C:$C,'P&L'!D$4) -> -1383 | E6: =-1*SUMIFS(Workings!$E:$E,Workings!$F:$F,'P&L'!$B6,Workings!$C:$C,'P&L'!E$4) -> -1367 | G6: =D6/C6-1 -> -0.012847966 | H6: =E6/D6-1 -> -0.011569053 | I6: =I5*I24 -> -1409.04 | J6: =J5*J24 -> -1451.3112 | K6: =K5*K24 -> -1494.8505 | L6: =L5*L24 -> -1539.6961 | M6: =M5*M24 -> -1585.8869
B7: Gross Profit | C7: =SUM(C5:C6) -> 1521 | D7: =SUM(D5:D6) -> 1601 | E7: =SUM(E5:E6) -> 1673 | G7: =D7/C7-1 -> 0.052596976 | H7: =E7/D7-1 -> 0.044971893 | I7: =SUM(I5:I6) -> 1722.16 | J7: =SUM(J5:J6) -> 1773.8248 | K7: =SUM(K5:K6) -> 1827.0395 | L7: =SUM(L5:L6) -> 1881.8507 | M7: =SUM(M5:M6) -> 1938.3063
B8: Operating expenses | C8: =-1*SUMIFS(Workings!$E:$E,Workings!$F:$F,'P&L'!$B8,Workings!$C:$C,'P&L'!C$4) -> -1212.18 | D8: =-1*SUMIFS(Workings!$E:$E,Workings!$F:$F,'P&L'!$B8,Workings!$C:$C,'P&L'!D$4) -> -1245.34 | E8: =-1*SUMIFS(Workings!$E:$E,Workings!$F:$F,'P&L'!$B8,Workings!$C:$C,'P&L'!E$4) -> -1068.24 | G8: =D8/C8-1 -> 0.027355673 | H8: =E8/D8-1 -> -0.14221016 | I8: =I5*I29 -> -1095.92 | J8: =J5*J29 -> -1128.7976 | K8: =K5*K29 -> -1162.6615 | L8: =L5*L29 -> -1197.5414 | M8: =M5*M29 -> -1233.4676
B9: EBITDA | C9: =SUM(C7:C8) -> 308.82 | D9: =SUM(D7:D8) -> 355.66 | E9: =SUM(E7:E8) -> 604.76 | G9: =D9/C9-1 -> 0.15167411 | H9: =E9/D9-1 -> 0.70038801 | I9: =SUM(I7:I8) -> 626.24 | J9: =SUM(J7:J8) -> 645.0272 | K9: =SUM(K7:K8) -> 664.37802 | L9: =SUM(L7:L8) -> 684.30936 | M9: =SUM(M7:M8) -> 704.83864
B10: D&A | C10: =-1*SUMIFS(Workings!$E:$E,Workings!$F:$F,'P&L'!$B10,Workings!$C:$C,'P&L'!C$4) -> -31 | D10: =-1*SUMIFS(Workings!$E:$E,Workings!$F:$F,'P&L'!$B10,Workings!$C:$C,'P&L'!D$4) -> -44 | E10: =-1*SUMIFS(Workings!$E:$E,Workings!$F:$F,'P&L'!$B10,Workings!$C:$C,'P&L'!E$4) -> -41 | G10: =D10/C10-1 -> 0.41935484 | H10: =E10/D10-1 -> -0.068181818 | I10: ='PP&E'!F7 -> -44.314229 | J10: ='PP&E'!G7 -> -45.260067 | K10: ='PP&E'!H7 -> -46.226092 | L10: ='PP&E'!I7 -> -47.212736 | M10: ='PP&E'!J7 -> -48.220438
B11: EBIT | C11: =SUM(C9:C10) -> 277.82 | D11: =SUM(D9:D10) -> 311.66 | E11: =SUM(E9:E10) -> 563.76 | G11: =D11/C11-1 -> 0.12180549 | H11: =E11/D11-1 -> 0.80889431 | I11: =SUM(I9:I10) -> 581.92577 | J11: =SUM(J9:J10) -> 599.76713 | K11: =SUM(K9:K10) -> 618.15192 | L11: =SUM(L9:L10) -> 637.09662 | M11: =SUM(M9:M10) -> 656.6182
B12: Interest expenses | C12: =-1*SUMIFS(Workings!$E:$E,Workings!$F:$F,'P&L'!$B12,Workings!$C:$C,'P&L'!C$4) -> -56 | D12: =-1*SUMIFS(Workings!$E:$E,Workings!$F:$F,'P&L'!$B12,Workings!$C:$C,'P&L'!D$4) -> -65 | E12: =-1*SUMIFS(Workings!$E:$E,Workings!$F:$F,'P&L'!$B12,Workings!$C:$C,'P&L'!E$4) -> -52 | G12: =D12/C12-1 -> 0.16071429 | H12: =E12/D12-1 -> -0.2 | I12: ='Financial Liabilities'!C17 -> -54.45 | J12: ='Financial Liabilities'!D17 -> -50.866096 | K12: ='Financial Liabilities'!E17 -> -46.959641 | L12: ='Financial Liabilities'!F17 -> -42.701605 | M12: ='Financial Liabilities'!G17 -> -38.060345
B13: EBT | C13: =SUM(C11:C12) -> 221.82 | D13: =SUM(D11:D12) -> 246.66 | E13: =SUM(E11:E12) -> 511.76 | G13: =D13/C13-1 -> 0.11198269 | H13: =E13/D13-1 -> 1.0747588 | I13: =SUM(I11:I12) -> 527.47577 | J13: =SUM(J11:J12) -> 548.90104 | K13: =SUM(K11:K12) -> 571.19228 | L13: =SUM(L11:L12) -> 594.39502 | M13: =SUM(M11:M12) -> 618.55785
B14: Taxes | C14: =-1*SUMIFS(Workings!$E:$E,Workings!$F:$F,'P&L'!$B14,Workings!$C:$C,'P&L'!C$4) -> -207.52 | D14: =-1*SUMIFS(Workings!$E:$E,Workings!$F:$F,'P&L'!$B14,Workings!$C:$C,'P&L'!D$4) -> -209.98 | E14: =-1*SUMIFS(Workings!$E:$E,Workings!$F:$F,'P&L'!$B14,Workings!$C:$C,'P&L'!E$4) -> -208.58 | G14: =D14/C14-1 -> 0.011854279 | H14: =E14/D14-1 -> -0.0066673016 | I14: =I13*I34 -> -184.61652 | J14: =J13*J34 -> -192.11536 | K14: =K13*K34 -> -199.9173 | L14: =L13*L34 -> -208.03826 | M14: =M13*M34 -> -216.49525
B15: Net Income | C15: =SUM(C13:C14) -> 14.3 | D15: =SUM(D13:D14) -> 36.68 | E15: =SUM(E13:E14) -> 303.18 | G15: =D15/C15-1 -> 1.565035 | H15: =E15/D15-1 -> 7.2655398 | I15: =SUM(I13:I14) -> 342.85925 | J15: =SUM(J13:J14) -> 356.78567 | K15: =SUM(K13:K14) -> 371.27498 | L15: =SUM(L13:L14) -> 386.35676 | M15: =SUM(M13:M14) -> 402.0626
B17: Scenarios
B19: Revenue % growth | I19: =VLOOKUP($C$3,$B$19:$M$32,COLUMNS($B20:I22),FALSE) -> 0.03 | J19: =VLOOKUP($C$3,$B$19:$M$32,COLUMNS($B20:J22),FALSE) -> 0.03 | K19: =VLOOKUP($C$3,$B$19:$M$32,COLUMNS($B20:K22),FALSE) -> 0.03 | L19: =VLOOKUP($C$3,$B$19:$M$32,COLUMNS($B20:L22),FALSE) -> 0.03 | M19: =VLOOKUP($C$3,$B$19:$M$32,COLUMNS($B20:M22),FALSE) -> 0.03
B20: Best case | I20: 0.03 | J20: 0.03 | K20: 0.03 | L20: 0.03 | M20: 0.03
B21: Base Case | I21: 0.02 | J21: 0.02 | K21: 0.02 | L21: 0.02 | M21: 0.02
B22: Worst Case | I22: 0.01 | J22: 0.01 | K22: 0.01 | L22: 0.01 | M22: 0.01
B24: Cogs as % of Revenue | I24: =CHOOSE(MATCH($C$3,$B$25:$B$27,0),I25,I26,I27) -> -0.45 | J24: =CHOOSE(MATCH($C$3,$B$25:$B$27,0),J25,J26,J27) -> -0.45 | K24: =CHOOSE(MATCH($C$3,$B$25:$B$27,0),K25,K26,K27) -> -0.45 | L24: =CHOOSE(MATCH($C$3,$B$25:$B$27,0),L25,L26,L27) -> -0.45 | M24: =CHOOSE(MATCH($C$3,$B$25:$B$27,0),M25,M26,M27) -> -0.45
B25: Best case | C25: =C6/C5 -> -0.47946612 | D25: =D6/D5 -> -0.46347185 | E25: =E6/E5 -> -0.44967105 | I25: -0.45 | J25: -0.45 | K25: -0.45 | L25: -0.45 | M25: -0.45
B26: Base Case | C26: -0.47946612 | D26: -0.46347185 | E26: -0.44967105 | I26: -0.46347185 | J26: -0.46347185 | K26: -0.46347185 | L26: -0.46347185 | M26: -0.46347185
B27: Worst Case | C27: -0.47946612 | D27: -0.46347185 | E27: -0.44967105 | I27: -0.47946612 | J27: -0.47946612 | K27: -0.47946612 | L27: -0.47946612 | M27: -0.47946612
B29: Opex as % of Revenue | I29: =CHOOSE(MATCH($C$3,$B$25:$B$27,0),I30,I31,I32) -> -0.35 | J29: =CHOOSE(MATCH($C$3,$B$25:$B$27,0),J30,J31,J32) -> -0.35 | K29: =CHOOSE(MATCH($C$3,$B$25:$B$27,0),K30,K31,K32) -> -0.35 | L29: =CHOOSE(MATCH($C$3,$B$25:$B$27,0),L30,L31,L32) -> -0.35 | M29: =CHOOSE(MATCH($C$3,$B$25:$B$27,0),M30,M31,M32) -> -0.35
B30: Best case | C30: =C8/C5 -> -0.414846 | D30: =D8/D5 -> -0.41733914 | E30: =E8/E5 -> -0.35139474 | I30: -0.35 | J30: -0.35 | K30: -0.35 | L30: -0.35 | M30: -0.35
B31: Base Case | C31: -0.414846 | D31: -0.41733914 | E31: -0.35139474 | I31: -0.41 | J31: -0.41 | K31: -0.41 | L31: -0.41 | M31: -0.41
B32: Worst Case | C32: -0.414846 | D32: -0.41733914 | E32: -0.35139474 | I32: -0.42 | J32: -0.42 | K32: -0.42 | L32: -0.42 | M32: -0.42
B34: Taxes | I34: -0.35 | J34: -0.35 | K34: -0.35 | L34: -0.35 | M34: -0.35

Sheet BS
B2: Balance Sheet
F5: Forecast
B6: $ in million | C6: 42004 | D6: 42369 | E6: 42735 | F6: =E6+365 -> 43100 | G6: =F6+365 -> 43465 | H6: =G6+365 -> 43830 | I6: =H6+366 -> 44196 | J6: =I6+365 -> 44561
B7: Trade Receivables | C7: {=INDEX('BS 2014'!$1:$1048576,MATCH($B7,'BS 2014'!$A:$A,0),MATCH(C$6,'BS 2014'!$1:$1,0))} -> 143.9 | D7: {=INDEX('BS 2015'!$1:$1048576,MATCH($B7,'BS 2015'!$A:$A,0),MATCH(D$6,'BS 2015'!$1:$1,0))} -> 154.8 | E7: {=INDEX('BS 2016'!$1:$1048576,MATCH($B7,'BS 2016'!$A:$A,0),MATCH(E$6,'BS 2016'!$1:$1,0))} -> 169.3 | F7: =F21*'P&L'!I5/360 -> 163.67258 | G7: =G21*'P&L'!J5/360 -> 168.58276 | H7: =H21*'P&L'!K5/360 -> 173.64024 | I7: =I21*'P&L'!L5/360 -> 178.84945 | J7: =J21*'P&L'!M5/360 -> 184.21493
B8: Inventory | C8: {=INDEX('BS 2014'!$1:$1048576,MATCH($B8,'BS 2014'!$A:$A,0),MATCH(C$6,'BS 2014'!$1:$1,0))} -> 85 | D8: {=INDEX('BS 2015'!$1:$1048576,MATCH($B8,'BS 2015'!$A:$A,0),MATCH(D$6,'BS 2015'!$1:$1,0))} -> 92 | E8: {=INDEX('BS 2016'!$1:$1048576,MATCH($B8,'BS 2016'!$A:$A,0),MATCH(E$6,'BS 2016'!$1:$1,0))} -> 110 | F8: =-F23*'P&L'!I6/360 -> 97.534304 | G8: =-G23*'P&L'!J6/360 -> 100.46033 | H8: =-H23*'P&L'!K6/360 -> 103.47414 | I8: =-I23*'P&L'!L6/360 -> 106.57837 | J8: =-J23*'P&L'!M6/360 -> 109.77572
B9: PP&E | C9: {=INDEX('BS 2014'!$1:$1048576,MATCH($B9,'BS 2014'!$A:$A,0),MATCH(C$6,'BS 2014'!$1:$1,0))} -> 632.5 | D9: {=INDEX('BS 2015'!$1:$1048576,MATCH($B9,'BS 2015'!$A:$A,0),MATCH(D$6,'BS 2015'!$1:$1,0))} -> 632.5 | E9: {=INDEX('BS 2016'!$1:$1048576,MATCH($B9,'BS 2016'!$A:$A,0),MATCH(E$6,'BS 2016'!$1:$1,0))} -> 659.5 | F9: ='PP&E'!F9 -> 673.57628 | G9: ='PP&E'!G9 -> 687.95301 | H9: ='PP&E'!H9 -> 702.63659 | I9: ='PP&E'!I9 -> 717.63358 | J9: ='PP&E'!J9 -> 732.95066
B10: Cash | C10: {=INDEX('BS 2014'!$1:$1048576,MATCH($B10,'BS 2014'!$A:$A,0),MATCH(C$6,'BS 2014'!$1:$1,0))} -> 24.8 | D10: {=INDEX('BS 2015'!$1:$1048576,MATCH($B10,'BS 2015'!$A:$A,0),MATCH(D$6,'BS 2015'!$1:$1,0))} -> 21.8 | E10: {=INDEX('BS 2016'!$1:$1048576,MATCH($B10,'BS 2016'!$A:$A,0),MATCH(E$6,'BS 2016'!$1:$1,0))} -> 220 | F10: =E10+Cash!C20 -> 409.58712 | G10: =F10+Cash!D20 -> 559.82481 | H10: =G10+Cash!E20 -> 714.36122 | I10: =H10+Cash!F20 -> 873.18825 | J10: =I10+Cash!G20 -> 1036.2848
B11: Other assets | C11: {=INDEX('BS 2014'!$1:$1048576,MATCH($B11,'BS 2014'!$A:$A,0),MATCH(C$6,'BS 2014'!$1:$1,0))} -> 45.9 | D11: {=INDEX('BS 2015'!$1:$1048576,MATCH($B11,'BS 2015'!$A:$A,0),MATCH(D$6,'BS 2015'!$1:$1,0))} -> 46.9 | E11: {=INDEX('BS 2016'!$1:$1048576,MATCH($B11,'BS 2016'!$A:$A,0),MATCH(E$6,'BS 2016'!$1:$1,0))} -> 68 | F11: =F24*'P&L'!I5 -> 56.146589 | G11: =G24*'P&L'!J5 -> 57.830987 | H11: =H24*'P&L'!K5 -> 59.565916 | I11: =I24*'P&L'!L5 -> 61.352894 | J11: =J24*'P&L'!M5 -> 63.193481
B12: Assets | C12: =SUM(C7:C11) -> 932.1 | D12: =SUM(D7:D11) -> 948 | E12: =SUM(E7:E11) -> 1226.8 | F12: =SUM(F7:F11) -> 1400.5169 | G12: =SUM(G7:G11) -> 1574.6519 | H12: =SUM(H7:H11) -> 1753.6781 | I12: =SUM(I7:I11) -> 1937.6025 | J12: =SUM(J7:J11) -> 2126.4196
B14: Trade Payables | C14: {=INDEX('BS 2014'!$1:$1048576,MATCH($B14,'BS 2014'!$A:$A,0),MATCH(C$6,'BS 2014'!$1:$1,0))} -> 68 | D14: {=INDEX('BS 2015'!$1:$1048576,MATCH(B14,'BS 2015'!$A:$A,0),MATCH(D$6,'BS 2015'!$1:$1,0))} -> 68.9 | E14: {=INDEX('BS 2016'!$1:$1048576,MATCH(B14,'BS 2016'!$A:$A,0),MATCH(E$6,'BS 2016'!$1:$1,0))} -> 68.9 | F14: =-F22*'P&L'!I6/360 -> 69.868814 | G14: =-G22*'P&L'!J6/360 -> 71.964879 | H14: =-H22*'P&L'!K6/360 -> 74.123825 | I14: =-I22*'P&L'!L6/360 -> 76.34754 | J14: =-J22*'P&L'!M6/360 -> 78.637966
B15: Provisions | C15: {=INDEX('BS 2014'!$1:$1048576,MATCH($B15,'BS 2014'!$A:$A,0),MATCH(C$6,'BS 2014'!$1:$1,0))} -> 32.5 | D15: {=INDEX('BS 2015'!$1:$1048576,MATCH($B15,'BS 2015'!$A:$A,0),MATCH(D$6,'BS 2015'!$1:$1,0))} -> 28.7 | E15: {=INDEX('BS 2016'!$1:$1048576,MATCH(B15,'BS 2016'!$A:$A,0),MATCH(E$6,'BS 2016'!$1:$1,0))} -> 28.7 | F15: 28.7 | G15: 28.7 | H15: 28.7 | I15: 28.7 | J15: 28.7
B16: Financial Liabilities | C16: {=INDEX('BS 2014'!$1:$1048576,MATCH($B16,'BS 2014'!$A:$A,0),MATCH(C$6,'BS 2014'!$1:$1,0))} -> 615.8 | D16: {=INDEX('BS 2015'!$1:$1048576,MATCH($B16,'BS 2015'!$A:$A,0),MATCH(D$6,'BS 2015'!$1:$1,0))} -> 610.4 | E16: {=INDEX('BS 2016'!$1:$1048576,MATCH($B16,'BS 2016'!$A:$A,0),MATCH(E$6,'BS 2016'!$1:$1,0))} -> 605 | F16: ='Financial Liabilities'!F9 -> 565.17885 | G16: ='Financial Liabilities'!G9 -> 521.77379 | H16: ='Financial Liabilities'!H9 -> 474.46227 | I16: ='Financial Liabilities'!I9 -> 422.89272 | J16: ='Financial Liabilities'!J9 -> 366.68191
B17: Other liabilities | C17: {=INDEX('BS 2014'!$1:$1048576,MATCH($B17,'BS 2014'!$A:$A,0),MATCH(C$6,'BS 2014'!$1:$1,0))} -> 48.3 | D17: {=INDEX('BS 2015'!$1:$1048576,MATCH($B17,'BS 2015'!$A:$A,0),MATCH(D$6,'BS 2015'!$1:$1,0))} -> 43.3 | E17: {=INDEX('BS 2016'!$1:$1048576,MATCH($B17,'BS 2016'!$A:$A,0),MATCH(E$6,'BS 2016'!$1:$1,0))} -> 38.9 | F17: =F25*'P&L'!I5 -> 45.753669 | G17: =G25*'P&L'!J5 -> 47.126279 | H17: =H25*'P&L'!K5 -> 48.540068 | I17: =I25*'P&L'!L5 -> 49.99627 | J17: =J25*'P&L'!M5 -> 51.496158
B18: Equity | C18: {=INDEX('BS 2014'!$1:$1048576,MATCH($B18,'BS 2014'!$A:$A,0),MATCH(C$6,'BS 2014'!$1:$1,0))} -> 167.5 | D18: {=INDEX('BS 2015'!$1:$1048576,MATCH($B18,'BS 2015'!$A:$A,0),MATCH(D$6,'BS 2015'!$1:$1,0))} -> 196.7 | E18: {=INDEX('BS 2016'!$1:$1048576,MATCH($B18,'BS 2016'!$A:$A,0),MATCH(E$6,'BS 2016'!$1:$1,0))} -> 485.3 | F18: =Equity!F10 -> 691.01555 | G18: =Equity!G10 -> 905.08696 | H18: =Equity!H10 -> 1127.8519 | I18: =Equity!I10 -> 1359.666 | J18: =Equity!J10 -> 1600.9036
B19: Liabilities and Equity | C19: =SUM(C14:C18) -> 932.1 | D19: =SUM(D14:D18) -> 948 | E19: =SUM(E14:E18) -> 1226.8 | F19: =SUM(F14:F18) -> 1400.5169 | G19: =SUM(G14:G18) -> 1574.6519 | H19: =SUM(H14:H18) -> 1753.6781 | I19: =SUM(I14:I18) -> 1937.6025 | J19: =SUM(J14:J18) -> 2126.4196
B21: DSO | C21: =C7/'P&L'!C5*360 -> 17.728953 | D21: =D7/'P&L'!D5*360 -> 18.675603 | E21: =E7/'P&L'!E5*360 -> 20.048684 | F21: =AVERAGE(C21:E21) -> 18.817747 | G21: 18.817747 | H21: 18.817747 | I21: 18.817747 | J21: 18.817747
B22: DPO | C22: =-C14/'P&L'!C$6*360 -> 17.473233 | D22: =-D14/'P&L'!D6*360 -> 17.934924 | E22: =-E14/'P&L'!E6*360 -> 18.144843 | F22: =AVERAGE(C22:E22) -> 17.851 | G22: 17.851 | H22: 17.851 | I22: 17.851 | J22: 17.851
B23: DIO | C23: =-C8/'P&L'!C$6*360 -> 21.841542 | D23: =-D8/'P&L'!D$6*360 -> 23.947939 | E23: =-E8/'P&L'!E$6*360 -> 28.968544 | F23: =AVERAGE(C23:E23) -> 24.919342 | G23: 24.919342 | H23: 24.919342 | I23: 24.919342 | J23: 24.919342
B24: Other Assets % | C24: =C11/'P&L'!C$5 -> 0.015708419 | D24: =D11/'P&L'!D$5 -> 0.015717158 | E24: =E11/'P&L'!E$5 -> 0.022368421 | F24: =AVERAGE(C24:E24) -> 0.017931333 | G24: 0.017931333 | H24: 0.017931333 | I24: 0.017931333 | J24: 0.017931333
B25: Other liabilities % | C25: =C17/'P&L'!C$5 -> 0.016529774 | D25: =D17/'P&L'!D$5 -> 0.014510724 | E25: =E17/'P&L'!E$5 -> 0.012796053 | F25: =AVERAGE(C25:E25) -> 0.014612184 | G25: 0.014612184 | H25: 0.014612184 | I25: 0.014612184 | J25: 0.014612184
B27: check | C27: =C12-C19 -> 0 | D27: =D12-D19 -> 0 | E27: =E12-E19 -> 0 | F27: =F12-F19 -> 0 | G27: =G12-G19 -> 0 | H27: =H12-H19 -> 0 | I27: =I12-I19 -> 0 | J27: =J12-J19 -> 0

Sheet Cash Flow Statement
B2: Cash Flow Statement
C4: 2015 | D4: 2016 | E4: 2017 | F4: 2018 | G4: 2019 | H4: 2020 | I4: 2021
B5: $ in million | C5: FY | D5: FY | E5: Forecast
B6: EBITDA | C6: ='P&L'!D9 -> 355.66 | D6: ='P&L'!E9 -> 604.76 | E6: ='P&L'!I9 -> 626.24 | F6: ='P&L'!J9 -> 645.0272 | G6: ='P&L'!K9 -> 664.37802 | H6: ='P&L'!L9 -> 684.30936 | I6: ='P&L'!M9 -> 704.83864
B8: Intrest Expenses | C8: ='P&L'!D12 -> -65 | D8: ='P&L'!E12 -> -52 | E8: ='P&L'!I12 -> -54.45 | F8: ='P&L'!J12 -> -50.866096 | G8: ='P&L'!K12 -> -46.959641 | H8: ='P&L'!L12 -> -42.701605 | I8: ='P&L'!M12 -> -38.060345
B9: Taxes | C9: ='P&L'!D14 -> -209.98 | D9: ='P&L'!E14 -> -208.58 | E9: ='P&L'!I14 -> -184.61652 | F9: ='P&L'!J14 -> -192.11536 | G9: ='P&L'!K14 -> -199.9173 | H9: ='P&L'!L14 -> -208.03826 | I9: ='P&L'!M14 -> -216.49525
B11: Changes in Inventory | C11: =-(BS!D8-BS!C8) -> -7 | D11: =-(BS!E8-BS!D8) -> -18 | E11: =-(BS!F8-BS!E8) -> 12.465696 | F11: =-(BS!G8-BS!F8) -> -2.9260291 | G11: =-(BS!H8-BS!G8) -> -3.01381 | H11: =-(BS!I8-BS!H8) -> -3.1042243 | I11: =-(BS!J8-BS!I8) -> -3.197351
B12: Changes in Accounts Receivable | C12: =-(BS!D7-BS!C7) -> -10.9 | D12: =-(BS!E7-BS!D7) -> -14.5 | E12: =-(BS!F7-BS!E7) -> 5.6274206 | F12: =-(BS!G7-BS!F7) -> -4.9101774 | G12: =-(BS!H7-BS!G7) -> -5.0574827 | H12: =-(BS!I7-BS!H7) -> -5.2092072 | I12: =-(BS!J7-BS!I7) -> -5.3654834
B13: Changes in Accounts Payable | C13: =BS!D14-BS!C14 -> 0.9 | D13: =BS!E14-BS!D14 -> 0 | E13: =BS!F14-BS!E14 -> 0.96881427 | F13: =BS!G14-BS!F14 -> 2.0960644 | G13: =BS!H14-BS!G14 -> 2.1589464 | H13: =BS!I14-BS!H14 -> 2.2237148 | I13: =BS!J14-BS!I14 -> 2.2904262
B14: Changes in provisions | C14: =BS!D15-BS!C15 -> -3.8 | D14: =BS!E15-BS!D15 -> 0 | E14: =BS!F15-BS!E15 -> 0 | F14: =BS!G15-BS!F15 -> 0 | G14: =BS!H15-BS!G15 -> 0 | H14: =BS!I15-BS!H15 -> 0 | I14: =BS!J15-BS!I15 -> 0
B15: Changes in Other Liabilties | C15: =BS!D17-BS!C17 -> -5 | D15: =BS!E17-BS!D17 -> -4.4 | E15: =BS!F17-BS!E17 -> 6.8536691 | F15: =BS!G17-BS!F17 -> 1.3726101 | G15: =BS!H17-BS!G17 -> 1.4137884 | H15: =BS!I17-BS!H17 -> 1.456202 | I15: =BS!J17-BS!I17 -> 1.4998881
B16: Changes in Other Assests | C16: =-(BS!D11-BS!C11) -> -1 | D16: =-(BS!E11-BS!D11) -> -21.1 | E16: =-(BS!F11-BS!E11) -> 11.853411 | F16: =-(BS!G11-BS!F11) -> -1.6843977 | G16: =-(BS!H11-BS!G11) -> -1.7349296 | H16: =-(BS!I11-BS!H11) -> -1.7869775 | I16: =-(BS!J11-BS!I11) -> -1.8405868
B17: Cash Flow from Operating Activities | C17: =SUM(C6:C16) -> 53.88 | D17: =SUM(D6:D16) -> 286.18 | E17: =SUM(E6:E16) -> 424.94249 | F17: =SUM(F6:F16) -> 395.99381 | G17: =SUM(G6:G16) -> 411.26759 | H17: =SUM(H6:H16) -> 427.149 | I17: =SUM(I6:I16) -> 443.66994
B19: CAPEX | C19: =-(BS!D9-BS!C9-'P&L'!D10) -> -44 | D19: =-(BS!E9-BS!D9-'P&L'!E10) -> -68 | E19: =-'PP&E'!F8 -> -58.390514 | F19: =-'PP&E'!G8 -> -59.636794 | G19: =-'PP&E'!H8 -> -60.909674 | H19: =-'PP&E'!I8 -> -62.209722 | I19: =-'PP&E'!J8 -> -63.537519
B20: Cash Flow from Investing Activities | C20: =SUM(C19) -> -44 | D20: =SUM(D19) -> -68 | E20: =SUM(E19) -> -58.390514 | F20: =SUM(F19) -> -59.636794 | G20: =SUM(G19) -> -60.909674 | H20: =SUM(H19) -> -62.209722 | I20: =SUM(I19) -> -63.537519
B22: Borrowings | C22: =BS!D16-BS!C16 -> -5.4 | D22: =BS!E16-BS!D16 -> -5.4 | E22: =BS!F16-BS!E16 -> -39.821154 | F22: =BS!G16-BS!F16 -> -43.405058 | G22: =BS!H16-BS!G16 -> -47.311514 | H22: =BS!I16-BS!H16 -> -51.56955 | I22: =BS!J16-BS!I16 -> -56.210809
B23: Changes in Equity and Dividends | C23: =BS!D18-BS!C18-'P&L'!D15 -> -7.48 | D23: =BS!E18-BS!D18-'P&L'!E15 -> -14.58 | E23: =BS!F18-BS!E18-'P&L'!I15 -> -137.1437 | F23: =BS!G18-BS!F18-'P&L'!J15 -> -142.71427 | G23: =BS!H18-BS!G18-'P&L'!K15 -> -148.50999 | H23: =BS!I18-BS!H18-'P&L'!L15 -> -154.5427 | I23: =BS!J18-BS!I18-'P&L'!M15 -> -160.82504
B24: Cash Flow from Financing Activities | C24: =SUM(C22:C23) -> -12.88 | D24: =SUM(D22:D23) -> -19.98 | E24: =SUM(E22:E23) -> -176.96485 | F24: =SUM(F22:F23) -> -186.11933 | G24: =SUM(G22:G23) -> -195.82151 | H24: =SUM(H22:H23) -> -206.11225 | I24: =SUM(I22:I23) -> -217.03585
B26: Net Cash Flow | C26: =C17+C20+C24 -> -3 | D26: =D17+D20+D24 -> 198.2 | E26: =E17+E20+E24 -> 189.58712 | F26: =F17+F20+F24 -> 150.23769 | G26: =G17+G20+G24 -> 154.53641 | H26: =H17+H20+H24 -> 158.82703 | I26: =I17+I20+I24 -> 163.09657
B28: Cash at the beginning of the year | C28: =BS!C10 -> 24.8 | D28: =C29 -> 21.8 | E28: =D29 -> 220 | F28: =E29 -> 409.58712 | G28: =F29 -> 559.82481 | H28: =G29 -> 714.36122 | I28: =H29 -> 873.18825
B29: Cash at the end of the year | C29: =BS!D10 -> 21.8 | D29: =BS!E10 -> 220 | E29: =BS!F10 -> 409.58712 | F29: =BS!G10 -> 559.82481 | G29: =BS!H10 -> 714.36122 | H29: =BS!I10 -> 873.18825 | I29: =BS!J10 -> 1036.2848
B31: check | C31: =C28+C26-C29 -> 0 | D31: =D28+D26-D29 -> 0 | E31: =E28+E26-E29 -> 5.1159077e-13 | F31: =F28+F26-F29 -> 0 | G31: =G28+G26-G29 -> 0 | H31: =H28+H26-H29 -> 0 | I31: =I28+I26-I29 -> 0

Sheet PP&E
B2: Fixed Assest Roll Forward
F4: Forecast
B5: $ in million | C5: 42004 | D5: 42369 | E5: 42735 | F5: =E5+365 -> 43100 | G5: =F5+365 -> 43465 | H5: =G5+365 -> 43830 | I5: =H5+366 -> 44196 | J5: =I5+365 -> 44561
B6: Beginning PP&E | D6: =C9 -> 632.5 | E6: =BS!D9 -> 632.5 | F6: =BS!E9 -> 659.5 | G6: =F9 -> 673.57628 | H6: =G9 -> 687.95301 | I6: =H9 -> 702.63659 | J6: =I9 -> 717.63358
B7: D&A | D7: ='P&L'!D10 -> -44 | E7: ='P&L'!E10 -> -41 | F7: =F6*F11 -> -44.314229 | G7: =G6*G11 -> -45.260067 | H7: =H6*H11 -> -46.226092 | I7: =I6*I11 -> -47.212736 | J7: =J6*J11 -> -48.220438
B8: Capex | D8: =D9-D7-D6 -> 44 | E8: =E9-E7-E6 -> 68 | F8: =F6*F12 -> 58.390514 | G8: =G6*G12 -> 59.636794 | H8: =H6*H12 -> 60.909674 | I8: =I6*I12 -> 62.209722 | J8: =J6*J12 -> 63.537519
B9: Ending PP&E | C9: =BS!C9 -> 632.5 | D9: =BS!D9 -> 632.5 | E9: =BS!E9 -> 659.5 | F9: =SUM(F6:F8) -> 673.57628 | G9: =SUM(G6:G8) -> 687.95301 | H9: =SUM(H6:H8) -> 702.63659 | I9: =SUM(I6:I8) -> 717.63358 | J9: =SUM(J6:J8) -> 732.95066
B11: D&A as % of Beggining PP&E | D11: =D7/D6 -> -0.069565217 | E11: =E7/E6 -> -0.064822134 | F11: =AVERAGE(D11:E11) -> -0.067193676 | G11: =AVERAGE(D11:E11) -> -0.067193676 | H11: =AVERAGE(F11:G11) -> -0.067193676 | I11: =AVERAGE(G11:H11) -> -0.067193676 | J11: =AVERAGE(H11:I11) -> -0.067193676
B12: Capex as % of Beggining PP&E | D12: =D8/D6 -> 0.069565217 | E12: =E8/E6 -> 0.10750988 | F12: =AVERAGE($D12:$E12) -> 0.088537549 | G12: =AVERAGE($D12:$E12) -> 0.088537549 | H12: =AVERAGE($D12:$E12) -> 0.088537549 | I12: =AVERAGE($D12:$E12) -> 0.088537549 | J12: =AVERAGE($D12:$E12) -> 0.088537549
B14: check | D14: =D6+D8+D7-D9 -> 0 | E14: =E6+E8+E7-E9 -> 0 | F14: =F6+F8+F7-F9 -> 0 | G14: =G6+G8+G7-G9 -> 0 | H14: =H6+H8+H7-H9 -> 0 | I14: =I6+I8+I7-I9 -> 0 | J14: =J6+J8+J7-J9 -> 0

Sheet Financial Liabilities
B2: Financial Liabilities
F4: Forecast
B5: $ in million | C5: 42004 | D5: 42369 | E5: 42735 | F5: =E5+365 -> 43100 | G5: =F5+365 -> 43465 | H5: =G5+365 -> 43830 | I5: =H5+366 -> 44196 | J5: =I5+365 -> 44561
B6: Beginning Debt | D6: =C9 -> 615.8 | E6: =D9 -> 610.4 | F6: =E9 -> 605 | G6: =F9 -> 565.17885 | H6: =G9 -> 521.77379 | I6: =H9 -> 474.46227 | J6: =I9 -> 422.89272
B7: New Debt | D7: 0 | E7: 0 | F7: 0 | G7: 0 | H7: 0 | I7: 0 | J7: 0
B8: Principal Repayments | D8: =BS!D16-BS!C16 -> -5.4 | E8: =BS!E16-BS!D16 -> -5.4 | F8: =C19-E9 -> -39.821154 | G8: =D19-F9 -> -43.405058 | H8: =E19-G9 -> -47.311514 | I8: =F19-H9 -> -51.56955 | J8: =G19-I9 -> -56.210809
B9: Ending Debt | C9: =BS!C16 -> 615.8 | D9: =SUM(D6:D8) -> 610.4 | E9: =SUM(E6:E8) -> 605 | F9: =SUM(F6:F8) -> 565.17885 | G9: =SUM(G6:G8) -> 521.77379 | H9: =SUM(H6:H8) -> 474.46227 | I9: =SUM(I6:I8) -> 422.89272 | J9: =SUM(J6:J8) -> 366.68191
B11: Debt to be paid in years | C11: 10
B12: Intrest rate | C12: 0.09
B13: Annual repayment | C13: =PMT(C12,C11,E9) -> -94.271154
B15: Period | C15: 1 | D15: 2 | E15: 3 | F15: 4 | G15: 5 | H15: 6 | I15: 7 | J15: 8 | K15: 9 | L15: 10
B16: Annual repayment | C16: =C13 -> -94.271154 | D16: -94.271154 | E16: -94.271154 | F16: -94.271154 | G16: -94.271154 | H16: -94.271154 | I16: -94.271154 | J16: -94.271154 | K16: -94.271154 | L16: -94.271154
B17: Intrest Expense | C17: =-E9*C12 -> -54.45 | D17: =-C19*$C$12 -> -50.866096 | E17: =-D19*$C$12 -> -46.959641 | F17: =-E19*$C$12 -> -42.701605 | G17: =-F19*$C$12 -> -38.060345 | H17: =-G19*$C$12 -> -33.001372 | I17: =-H19*$C$12 -> -27.487092 | J17: =-I19*$C$12 -> -21.476526 | K17: =-J19*$C$12 -> -14.92501 | L17: =-K19*$C$12 -> -7.7838568
B18: Debt Repayment | C18: =C16-C17 -> -39.821154 | D18: =D16-D17 -> -43.405058 | E18: =E16-E17 -> -47.311514 | F18: =F16-F17 -> -51.56955 | G18: =G16-G17 -> -56.210809 | H18: =H16-H17 -> -61.269782 | I18: =I16-I17 -> -66.784062 | J18: =J16-J17 -> -72.794628 | ... L18: =L16-L17 -> -86.487298
B19: Residual Debt | C19: =E9+C18 -> 565.17885 | D19: =C19+D18 -> 521.77379 | E19: =D19+E18 -> 474.46227 | F19: =E19+F18 -> 422.89272 | G19: =F19+G18 -> 366.68191 | H19: =G19+H18 -> 305.41213 | I19: =H19+I18 -> 238.62807 | J19: =I19+J18 -> 165.83344 | K19: =J19+K18 -> 86.487298 | L19: =K19+L18 -> 7.8159701e-13

Sheet Equity
B2: Equity Schedule
F4: Forecast
B5: $ in million | C5: 42004 | D5: 42369 | E5: 42735 | F5: =E5+365 -> 43100 | G5: =F5+365 -> 43465 | H5: =G5+365 -> 43830 | I5: =H5+366 -> 44196 | J5: =I5+365 -> 44561
B6: Beginning Equity | F6: =E10 -> 485.3 | G6: =F10 -> 691.01555 | H6: =G10 -> 905.08696 | I6: =H10 -> 1127.8519 | J6: =I10 -> 1359.666
B7: Increase of capital | F7: 0 | G7: 0 | H7: 0 | I7: 0 | J7: 0
B8: Net Income (loss) | F8: ='P&L'!I15 -> 342.85925 | G8: ='P&L'!J15 -> 356.78567 | H8: ='P&L'!K15 -> 371.27498 | I8: ='P&L'!L15 -> 386.35676 | J8: ='P&L'!M15 -> 402.0626
B9: Dividends | F9: =-IF(F8>0,F8*F12,0) -> -137.1437 | G9: =-IF(G8>0,G8*G12,0) -> -142.71427 | H9: =-IF(H8>0,H8*H12,0) -> -148.50999 | I9: =-IF(I8>0,I8*I12,0) -> -154.5427 | J9: =-IF(J8>0,J8*J12,0) -> -160.82504
B10: Ending equity | E10: =BS!E18 -> 485.3 | F10: =SUM(F6:F9) -> 691.01555 | G10: =SUM(G6:G9) -> 905.08696 | H10: =SUM(H6:H9) -> 1127.8519 | I10: =SUM(I6:I9) -> 1359.666 | J10: =SUM(J6:J9) -> 1600.9036
B12: Dividends as a % of Net Income | F12: 0.4 | G12: 0.4 | H12: 0.4 | I12: 0.4 | J12: 0.4

Sheet Cash
B2: Cash Flow Schedule
C4: Forecast
B5: $ in million | C5: 2017 | D5: 2018 | E5: 2019 | F5: 2020 | G5: 2021
B6: EBITDA | C6: ='P&L'!I9 -> 626.24 | D6: ='P&L'!J9 -> 645.0272 | E6: ='P&L'!K9 -> 664.37802 | F6: ='P&L'!L9 -> 684.30936 | G6: ='P&L'!M9 -> 704.83864
B7: Intrest Expense | C7: ='P&L'!I12 -> -54.45 | D7: ='P&L'!J12 -> -50.866096 | E7: ='P&L'!K12 -> -46.959641 | F7: ='P&L'!L12 -> -42.701605 | G7: ='P&L'!M12 -> -38.060345
B8: Taxes | C8: ='P&L'!I14 -> -184.61652 | D8: ='P&L'!J14 -> -192.11536 | E8: ='P&L'!K14 -> -199.9173 | F8: ='P&L'!L14 -> -208.03826 | G8: ='P&L'!M14 -> -216.49525
B9: Changes in Trade Receivables | C9: =-(BS!F7-BS!E7) -> 5.6274206 | D9: =-(BS!G7-BS!F7) -> -4.9101774 | E9: =-(BS!H7-BS!G7) -> -5.0574827 | F9: =-(BS!I7-BS!H7) -> -5.2092072 | G9: =-(BS!J7-BS!I7) -> -5.3654834
B10: Changes in Inventory | C10: =-(BS!F8-BS!E8) -> 12.465696 | D10: =-(BS!G8-BS!F8) -> -2.9260291 | E10: =-(BS!H8-BS!G8) -> -3.01381 | F10: =-(BS!I8-BS!H8) -> -3.1042243 | G10: =-(BS!J8-BS!I8) -> -3.197351
B11: Changes in Trade payables | C11: =BS!F14-BS!E14 -> 0.96881427 | D11: =BS!G14-BS!F14 -> 2.0960644 | E11: =BS!H14-BS!G14 -> 2.1589464 | F11: =BS!I14-BS!H14 -> 2.2237148 | G11: =BS!J14-BS!I14 -> 2.2904262
B12: Changes in Other Assets | C12: =-(BS!F11-BS!E11) -> 11.853411 | D12: =-(BS!G11-BS!F11) -> -1.6843977 | E12: =-(BS!H11-BS!G11) -> -1.7349296 | F12: =-(BS!I11-BS!H11) -> -1.7869775 | G12: =-(BS!J11-BS!I11) -> -1.8405868
B13: Changes in Other liabilities | C13: =BS!F17-BS!E17 -> 6.8536691 | D13: =BS!G17-BS!F17 -> 1.3726101 | E13: =BS!H17-BS!G17 -> 1.4137884 | F13: =BS!I17-BS!H17 -> 1.456202 | G13: =BS!J17-BS!I17 -> 1.4998881
B14: Capex | C14: =-'PP&E'!F8 -> -58.390514 | D14: =-'PP&E'!G8 -> -59.636794 | E14: =-'PP&E'!H8 -> -60.909674 | F14: =-'PP&E'!I8 -> -62.209722 | G14: =-'PP&E'!J8 -> -63.537519
B15: Net Operating Cash Flow | C15: =SUM(C6:C14) -> 366.55198 | D15: =SUM(D6:D14) -> 336.35702 | E15: =SUM(E6:E14) -> 350.35791 | F15: =SUM(F6:F14) -> 364.93928 | G15: =SUM(G6:G14) -> 380.13242
B16: Dividends | C16: =Equity!F9 -> -137.1437 | D16: =Equity!G9 -> -142.71427 | E16: =Equity!H9 -> -148.50999 | F16: =Equity!I9 -> -154.5427 | G16: =Equity!J9 -> -160.82504
B17: Change in Financial Liabilities | C17: =BS!F16-BS!E16 -> -39.821154 | D17: =BS!G16-BS!F16 -> -43.405058 | E17: =BS!H16-BS!G16 -> -47.311514 | F17: =BS!I16-BS!H16 -> -51.56955 | G17: =BS!J16-BS!I16 -> -56.210809
B18: Change in Provisions | C18: =BS!F15-BS!E15 -> 0 | D18: =BS!G15-BS!F15 -> 0 | E18: =BS!H15-BS!G15 -> 0 | F18: =BS!I15-BS!H15 -> 0 | G18: =BS!J15-BS!I15 -> 0
B19: Change in equity | C19: =BS!F18-BS!E18-Equity!F9-Equity!F8 -> 0 | D19: =BS!G18-BS!F18-Equity!G9-Equity!G8 -> 0 | E19: =BS!H18-BS!G18-Equity!H9-Equity!H8 -> 0 | F19: =BS!I18-BS!H18-Equity!I9-Equity!I8 -> 0 | G19: =BS!J18-BS!I18-Equity!J9-Equity!J8 -> 0
B20: Net Cash flow | C20: =SUM(C15:C19) -> 189.58712 | D20: =SUM(D15:D19) -> 150.23769 | E20: =SUM(E15:E19) -> 154.53641 | F20: =SUM(F15:F19) -> 158.82703 | G20: =SUM(G15:G19) -> 163.09657

Sheet Workings
B3: Date | C3: Year | D3: Financials | E3: Amount | F3: Mapping
B4: 41640 | C4: =YEAR(B4) -> 2014 | D4: Revenue - Supermarkets | E4: 72 | F4: Revenue
B5: 41640 | C5: =YEAR(B5) -> 2014 | D5: Cogs - Supermarkets | E5: 47 | F5: Cost of goods sold
B6: 41640 | C6: =YEAR(B6) -> 2014 | D6: Revenue - Discounters | E6: 37 | F6: Revenue
B7: 41640 | C7: =YEAR(B7) -> 2014 | D7: Cogs - Discounters | E7: 20 | F7: Cost of goods sold
B8: 41640 | C8: =YEAR(B8) -> 2014 | D8: Revenue - Grocery | E8: 36 | F8: Revenue
B9: 41640 | C9: =YEAR(B9) -> 2014 | D9: Cogs - Grocery | E9: 17 | F9: Cost of goods sold
B10: 41640 | C10: =YEAR(B10) -> 2014 | D10: Revenue - Retail | E10: 57 | F10: Revenue
B11: 41640 | C11: =YEAR(B11) -> 2014 | D11: Cogs - Retail | E11: 32 | F11: Cost of goods sold
B12: 41640 | C12: =YEAR(B12) -> 2014 | D12: Operating expenses | E12: 95.4 | F12: Operating expenses
B13: 41640 | C13: =YEAR(B13) -> 2014 | D13: D&A | E13: 2 | F13: D&A
B14: 41640 | C14: =YEAR(B14) -> 2014 | D14: Interest expenses | E14: 5 | F14: Interest expenses
B15: 41640 | C15: =YEAR(B15) -> 2014 | D15: Taxes | E15: 17.29 | F15: Taxes
... B438: 42705 | C438: =YEAR(B438) -> 2016 | D438: Other revenue | E438: 628 | F438: Revenue

Sheet Original Source
B3: Date | C3: Financials | D3: Amount
B4: 1.1.2014 | C4: Revenue - Supermarkets | D4: 72
B5: 1.1.2014 | C5: Cogs - Supermarkets | D5: 47
B6: 1.1.2014 | C6: Revenue - Discounters | D6: 37
B7: 1.1.2014 | C7: Cogs - Discounters | D7: 20
B8: 1.1.2014 | C8: Revenue - Grocery | D8: 36
B9: 1.1.2014 | C9: Cogs - Grocery | D9: 17
B10: 1.1.2014 | C10: Revenue - Retail | D10: 57
B11: 1.1.2014 | C11: Cogs - Retail | D11: 32
B12: 1.1.2014 | C12: Operating expenses | D12: 95.4
B13: 1.1.2014 | C13: D&A | D13: 2
B14: 1.1.2014 | C14: Interest expenses | D14: 5
B15: 1.1.2014 | C15: Taxes | D15: 17.29
... B438: 12.1.2016 | C438: Other revenue | D438: 628

Sheet BS 2014
A1: $ in mln | C1: 42004
A2: Receivables - Discounters | C2: 44.609
A3: Receivables - Other | C3: 33.097
A4: Receivables - Grocery | C4: 31.658
A5: Receivables - Retail | C5: 20.146
A6: Receivables - Supermarkets | C6: 14.39
A7: Trade Receivables | C7: 143.9
A9: Inventory - Discounters | C9: 29.75
A10: Inventory - Supermarkets | C10: 18.7
A11: Inventory - Grocery | C11: 16.15
A12: Inventory - Retail | C12: 11.05
A13: Inventory - Other | C13: 9.35
... A55: Liabilities & Equity | C55: 932.1

Sheet BS 2015
A1: $ in mln | B1: Code I | C1: 42369
A2: Receivables - Discounters | B2: R | C2: 40.248
A3: Receivables - Grocery | B3: R | C3: 34.056
A4: Receivables - Other | B4: R | C4: 29.412
A5: Receivables - Retail | B5: R | C5: 27.864
A6: Receivables - Supermarkets | B6: R | C6: 23.22
A7: Trade Receivables | C7: 154.8
A9: Inventory - Discounters | B9: I | C9: 24.84
A10: Inventory - Supermarkets | B10: I | C10: 20.24
A11: Inventory - Grocery | B11: I | C11: 17.48
A12: Inventory - Other | B12: I | C12: 17.48
A13: Inventory - Retail | B13: I | C13: 11.96
A14: Inventory | B14: I | C14: 92
A16: PP&E - Machinery | B16: P | C16: 346.475
A17: PP&E - Other | B17: P | C17: 139.525
A18: PP&E - IT | B18: P | C18: 125.575
A19: PP&E - Vehicles | B19: P | C19: 20.925
A20: PP&E | B20: P | C20: 632.5
A22: Cash - Bank Accounts | B22: C | C22: 13.298
... A24: Cash - Cash at hand | B24: C | C24: 3.052
A25: Cash | C25: 21.8
A27: Other assets | B27: O | C27: 46.9
A28: Other assets | C28: 46.9
A30: Assets | C30: 948
A32: Trade Payables - Discounters | B32: T | C32: 19.981
A33: Trade Payables - Retail | B33: T | C33: 15.847
A34: Trade Payables - Other | B34: T | C34: 14.469
A35: Trade Payables - Grocery | B35: T | C35: 10.335
A36: Trade Payables - Supermarkets | B36: T | C36: 8.268
A37: Trade Payables | C37: 68.9
A39: Provisions - Taxes | B39: P | C39: 17.507
A40: Provisions - Legal | B40: P | C40: 6.601
A41: Provisions - Other | B41: P | C41: 4.592
A42: Provisions | C42: 28.7
A44: Financial Liabilities vs. Banks | B44: F | C44: 610.4
A45: Financial Liabilities | C45: 610.4
A47: Other liabilities | B47: O | C47: 43.3
A48: Other liabilities | C48: 43.3
A50: Retained Earnings | B50: E | C50: 161.525
A51: Minority interest | B51: E | C51: 18.425
...

Sheet BS 2016
A1: $ in mln | B1: Code I | C1: Code II | D1: 42735
A2: Receivables - Discounters | B2: R | C2: A | D2: 44.018
A3: Receivables - Grocery | B3: R | C3: A | D3: 40.632
A4: Receivables - Other | B4: R | C4: A | D4: 32.167
A5: Receivables - Retail | B5: R | C5: A | D5: 27.088
A6: Receivables - Supermarkets | B6: R | C6: A | D6: 25.395
A7: Trade Receivables | D7: 169.3
A9: Inventory - Discounters | B9: I | C9: A | D9: 26.4
A10: Inventory - Supermarkets | B10: I | C10: A | D10: 25.3
A11: Inventory - Grocery | B11: I | C11: A | D11: 20.9
A12: Inventory - Other | B12: I | C12: A | D12: 20.9
A13: Inventory - Retail | B13: I | C13: A | D13: 16.5
A14: Inventory | B14: I | D14: 110
A16: PP&E - Machinery | B16: P | C16: A | D16: 350.51
A17: PP&E - Other | B17: P | C17: A | D17: 146.71
A18: PP&E - IT | B18: P | C18: A | D18: 133.735
A19: PP&E - Vehicles | B19: P | C19: A | D19: 28.545
A20: PP&E | D20: 659.5
A22: Cash - Bank Accounts | B22: C | C22: A | D22: 125.4
A23: Cash - T-bills | B23: C | C23: A | D23: 59.4
A24: Cash - Cash at hand | B24: C | C24: A | D24: 35.2
A25: Cash | D25: 220
A27: Other assets | B27: O | C27: A | D27: 68
A28: Other assets | D28: 68
A30: Assets | D30: 1226.8
A32: Trade Payables - Discounters | B32: T | C32: L | D32: 19.981
A33: Trade Payables - Retail | B33: T | C33: L | D33: 15.847
A34: Trade Payables - Other | B34: T | C34: L | D34: 14.469
A35: Trade Payables - Grocery | B35: T | C35: L | D35: 10.335
A36: Trade Payables - Supermarkets | B36: T | C36: L | D36: 8.268
A37: Trade Payables | D37: 68.9
A39: Provisions - Taxes | B39: P | C39: L | D39: 17.507
A40: Provisions - Legal | B40: P | C40: L | D40: 6.601
A41: Provisions - Other | B41: P | C41: L | D41: 4.592
A42: Provisions | D42: 28.7
A44: Financial Liabilities vs. Banks | B44: F | C44: L | D44: 605
A45: Financial Liabilities | D45: 605
A47: Other liabilities | B47: O | C47: L | D47: 38.9
A48: Other liabilities | D48: 38.9
A50: Retained Earnings | B50: E | C50: E | D50: 450.125
...

Sheet Notes
A3: DSO | B3: It tells you how quickly the company collects money from customers.
A4: DIO | B4: It tells you how many days inventory remains before being sold.
A5: DPO | B5: It tells you how long the company takes to pay suppliers.
A6: Asset Turnover
A7: Cash Conversion cycle
